[2023-09-22 20:50:53,341]160numexpr.utils-INFO-NumExpr defaulting to 6 threads.
[2023-09-22 20:50:53,750]361flask_cors.core-WARNING-Unknown option passed to Flask-CORS: support_credentials
[2023-09-22 20:50:53,750]361flask_cors.core-WARNING-Unknown option passed to Flask-CORS: support_credentials
[2023-09-22 20:50:53,769]187werkzeug-INFO-[31m[1mWARNING: This is a development server. Do not use it in a production deployment. Use a production WSGI server instead.[0m
 * Running on http://127.0.0.1:5000
[2023-09-22 20:50:53,769]187werkzeug-INFO-[33mPress CTRL+C to quit[0m
[2023-09-22 20:51:01,809]1414app-ERROR-Exception on /ask [POST]
Traceback (most recent call last):
  File "D:\Marvel\eds\newone\Lib\site-packages\langchain\vectorstores\faiss.py", line 47, in dependable_faiss_import
    import faiss
ModuleNotFoundError: No module named 'faiss'

During handling of the above exception, another exception occurred:

Traceback (most recent call last):
  File "D:\Marvel\eds\app.py", line 73, in ask_question
    vectordb = FAISS.from_documents(texts, embedding)
               ^^^^^^^^^^^^^^^^^^^^^^^^^^^^^^^^^^^^^^
  File "D:\Marvel\eds\newone\Lib\site-packages\langchain\vectorstores\base.py", line 417, in from_documents
    return cls.from_texts(texts, embedding, metadatas=metadatas, **kwargs)
           ^^^^^^^^^^^^^^^^^^^^^^^^^^^^^^^^^^^^^^^^^^^^^^^^^^^^^^^^^^^^^^^
  File "D:\Marvel\eds\newone\Lib\site-packages\langchain\vectorstores\faiss.py", line 603, in from_texts
    return cls.__from(
           ^^^^^^^^^^^
  File "D:\Marvel\eds\newone\Lib\site-packages\langchain\vectorstores\faiss.py", line 557, in __from
    faiss = dependable_faiss_import()
            ^^^^^^^^^^^^^^^^^^^^^^^^^
  File "D:\Marvel\eds\newone\Lib\site-packages\langchain\vectorstores\faiss.py", line 49, in dependable_faiss_import
    raise ImportError(
ImportError: Could not import faiss python package. Please install it with `pip install faiss-gpu` (for CUDA supported GPU) or `pip install faiss-cpu` (depending on Python version).

During handling of the above exception, another exception occurred:

Traceback (most recent call last):
  File "D:\Marvel\eds\newone\Lib\site-packages\flask\app.py", line 2190, in wsgi_app
    response = self.full_dispatch_request()
               ^^^^^^^^^^^^^^^^^^^^^^^^^^^^
  File "D:\Marvel\eds\newone\Lib\site-packages\flask\app.py", line 1486, in full_dispatch_request
    rv = self.handle_user_exception(e)
         ^^^^^^^^^^^^^^^^^^^^^^^^^^^^^
  File "D:\Marvel\eds\newone\Lib\site-packages\flask_cors\extension.py", line 176, in wrapped_function
    return cors_after_request(app.make_response(f(*args, **kwargs)))
                                                ^^^^^^^^^^^^^^^^^^
  File "D:\Marvel\eds\newone\Lib\site-packages\flask\app.py", line 1484, in full_dispatch_request
    rv = self.dispatch_request()
         ^^^^^^^^^^^^^^^^^^^^^^^
  File "D:\Marvel\eds\newone\Lib\site-packages\flask\app.py", line 1469, in dispatch_request
    return self.ensure_sync(self.view_functions[rule.endpoint])(**view_args)
           ^^^^^^^^^^^^^^^^^^^^^^^^^^^^^^^^^^^^^^^^^^^^^^^^^^^^^^^^^^^^^^^^^
  File "D:\Marvel\eds\app.py", line 82, in ask_question
    return jsonify({'message':"Error while processing","error":e})
           ^^^^^^^^^^^^^^^^^^^^^^^^^^^^^^^^^^^^^^^^^^^^^^^^^^^^^^^
  File "D:\Marvel\eds\newone\Lib\site-packages\flask\json\__init__.py", line 170, in jsonify
    return current_app.json.response(*args, **kwargs)
           ^^^^^^^^^^^^^^^^^^^^^^^^^^^^^^^^^^^^^^^^^^
  File "D:\Marvel\eds\newone\Lib\site-packages\flask\json\provider.py", line 215, in response
    f"{self.dumps(obj, **dump_args)}\n", mimetype=self.mimetype
       ^^^^^^^^^^^^^^^^^^^^^^^^^^^^
  File "D:\Marvel\eds\newone\Lib\site-packages\flask\json\provider.py", line 180, in dumps
    return json.dumps(obj, **kwargs)
           ^^^^^^^^^^^^^^^^^^^^^^^^^
  File "C:\Program Files\Python311\Lib\json\__init__.py", line 238, in dumps
    **kw).encode(obj)
          ^^^^^^^^^^^
  File "C:\Program Files\Python311\Lib\json\encoder.py", line 200, in encode
    chunks = self.iterencode(o, _one_shot=True)
             ^^^^^^^^^^^^^^^^^^^^^^^^^^^^^^^^^^
  File "C:\Program Files\Python311\Lib\json\encoder.py", line 258, in iterencode
    return _iterencode(o, 0)
           ^^^^^^^^^^^^^^^^^
  File "D:\Marvel\eds\newone\Lib\site-packages\flask\json\provider.py", line 120, in _default
    raise TypeError(f"Object of type {type(o).__name__} is not JSON serializable")
TypeError: Object of type ImportError is not JSON serializable
[2023-09-22 20:51:01,871]187werkzeug-INFO-127.0.0.1 - - [22/Sep/2023 20:51:01] "[35m[1mPOST /ask HTTP/1.1[0m" 500 -
